<?xml version="1.0"?>
<robot name="barista_robot">

  <!-- Base Link -->
  <link name="base_link">
    <visual>
      <geometry>
        <cylinder length="0.155" radius="0.178" />
      </geometry>
    </visual>
    <collision>
      <geometry>
        <cylinder length="0.155" radius="0.178" />
      </geometry>
    </collision>
    <inertial>
      <mass value="0.5"/>
      <origin rpy="0 0 0" xyz="0 0 0"/>
      <inertia ixx="0.004961541667" ixy="0" ixz="0" iyy="0.004961541667" iyz="0" izz="0.007921"/>
    </inertial>
  </link>

  <!-- Wheel Left -->
  <link name="left_wheel">      
    <visual>
      <origin rpy="0 1.5707 1.5707" xyz="0 0 0"/>
      <geometry>
        <cylinder length="0.0206" radius="0.0352"/>
      </geometry>
    </visual>
    <collision>
      <origin rpy="0 1.5707 1.5707" xyz="0 0 0"/>
      <geometry>
        <cylinder length="0.0206" radius="0.0352"/>
      </geometry>
    </collision>
    <inertial>
      <origin rpy="0 1.5707 1.5707" xyz="0 0 0"/>
      <mass value="0.05"/>
      <inertia ixx="0.00001725616667" ixy="0" ixz="0" iyy="0.00001725616667" iyz="0" izz="0.000030976"/>
    </inertial>
  </link>

  <joint name="joint_left_wheel" type="continuous">
    <origin rpy="0 0 0" xyz="0 0.15 -0.0573"/>
    <child link="left_wheel"/>
    <parent link="base_link"/>
    <axis rpy="0 0 0" xyz="0 1 0"/>
    <limit effort="10000" velocity="1000"/>
    <joint_properties damping="1.0" friction="1.0"/>
  </joint>

  <!-- Wheel Right -->
  <link name="right_wheel">      
    <visual>
      <origin rpy="0 1.5707 1.5707" xyz="0 0 0"/>
      <geometry>
        <cylinder length="0.0206" radius="0.0352"/>
      </geometry>
    </visual>
    <collision>
      <origin rpy="0 1.5707 1.5707" xyz="0 0 0"/>
      <geometry>
        <cylinder length="0.0206" radius="0.0352"/>
      </geometry>
    </collision>
    <inertial>
      <origin rpy="0 1.5707 1.5707" xyz="0 0 0"/>
      <mass value="0.05"/>
      <inertia ixx="0.00001725616667" ixy="0" ixz="0" iyy="0.00001725616667" iyz="0" izz="0.000030976"/>
    </inertial>
  </link>

  <joint name="joint_right_wheel" type="continuous">  
    <origin rpy="0 0 0" xyz="0 -0.15 -0.0573"/>
    <child link="right_wheel"/>
    <parent link="base_link"/>
    <axis rpy="0 0 0" xyz="0 1 0"/>
    <limit effort="10000" velocity="1000"/>
    <joint_properties damping="1.0" friction="1.0"/>
  </joint>


  <!-- Caster Wheel Front -->
  <link name="front_yaw_link">
    <visual>
      <origin rpy="0 1.5707 1.5707" xyz="0 0 0"/>
      <geometry>          
        <cylinder length="0.001" radius="0.0045000000000000005"/>
      </geometry>
    </visual>
    <collision>
      <origin rpy="0 1.5707 1.5707" xyz="0 0 0"/>
      <geometry>
        <cylinder length="0.001" radius="0.0045000000000000005"/>
      </geometry>
    </collision>
    <inertial>
        <origin rpy="0 1.5707 1.5707" xyz="0 0 0"/>
        <mass value="0.001"/>
        <inertia ixx="5.145833333333334e-09" ixy="0" ixz="0" iyy="5.145833333333334e-09" iyz="0" izz="1.0125000000000003e-08"/>
    </inertial>
  </link>

  <joint name="front_yaw_joint" type="continuous">
    <origin rpy="0 0 0" xyz="0.15 0 -0.0775" />
    <parent link="base_link" />
    <child link="front_yaw_link" />
    <axis xyz="0 0 1" />
    <limit effort="1000.0" velocity="100.0" />
    <dynamics damping="0.0" friction="0.1"/>
  </joint>

  <link name="front_roll_link">
    <visual>
      <origin rpy="0 1.5707 1.5707" xyz="0 0 0"/>
      <geometry>
        <cylinder length="0.001" radius="0.0045000000000000005"/>
      </geometry>
    </visual>
    <collision>
      <origin rpy="0 1.5707 1.5707" xyz="0 0 0"/>
      <geometry>
        <cylinder length="0.001" radius="0.0045000000000000005"/>
      </geometry>
    </collision>
    <inertial>
        <origin rpy="0 1.5707 1.5707" xyz="0 0 0"/>
        <mass value="0.001"/>
        <inertia ixx="5.145833333333334e-09" ixy="0" ixz="0" iyy="5.145833333333334e-09" iyz="0" izz="1.0125000000000003e-08"/>
    </inertial>
  </link>

  <joint name="front_roll_joint" type="continuous">
    <origin rpy="0 0 0" xyz="0 0 0" />
    <parent link="front_yaw_link" />
    <child link="front_roll_link" />
    <axis xyz="1 0 0" />
    <limit effort="1000.0" velocity="100.0" />
    <dynamics damping="0.0" friction="0.1"/>
  </joint>

  <link name="front_pitch_link">
    <visual>
      <origin rpy="0 1.5707 1.5707" xyz="0 0 0"/>
      <geometry>
        <sphere radius="0.010"/>
      </geometry>
    </visual>

    <collision>
      <origin rpy="0 1.5707 1.5707" xyz="0 0 0"/>
      <geometry>
        <sphere radius="0.010"/>
      </geometry>
    </collision>

    <inertial>
      <origin rpy="0 1.5707 1.5707" xyz="0 0 0"/>
      <mass value="0.001"/>
      <inertia ixx="4e-08" ixy="0" ixz="0" iyy="4e-08" iyz="0" izz="4e-08"/>
    </inertial>
  </link>

  <joint name="front_pitch_joint" type="continuous">
    <origin rpy="0 0 0" xyz="0 0 0" />
    <parent link="front_roll_link" />
    <child link="front_pitch_link" />
    <axis xyz="0 1 0" />
    <limit effort="1000.0" velocity="100.0" />
    <dynamics damping="0.0" friction="0.1"/>
  </joint>

<!-- Caster Wheel Back -->
  <link name="back_yaw_link">
    <visual>
      <origin rpy="0 1.5707 1.5707" xyz="0 0 0"/>
      <geometry>
        <cylinder length="0.001" radius="0.0045000000000000005"/>
      </geometry>
    </visual>
    <collision>
      <origin rpy="0 1.5707 1.5707" xyz="0 0 0"/>
      <geometry>
        <cylinder length="0.001" radius="0.0045000000000000005"/>
      </geometry>
    </collision>
    <inertial>
        <origin rpy="0 1.5707 1.5707" xyz="0 0 0"/>
        <mass value="0.001"/>
        <inertia ixx="5.145833333333334e-09" ixy="0" ixz="0" iyy="5.145833333333334e-09" iyz="0" izz="1.0125000000000003e-08"/>
    </inertial>
  </link>

  <joint name="back_yaw_joint" type="continuous">
    <origin rpy="0 0 0" xyz="-0.15 0 -0.0775" />
    <parent link="base_link" />
    <child link="back_yaw_link" />
    <axis xyz="0 0 1" />
    <limit effort="1000.0" velocity="100.0" />
    <dynamics damping="0.0" friction="0.1"/>
  </joint>

  <link name="back_roll_link">
    <visual>
      <origin rpy="0 1.5707 1.5707" xyz="0 0 0"/>
      <geometry>
        <cylinder length="0.001" radius="0.0045000000000000005"/>
      </geometry>
    </visual>
    <collision>
      <origin rpy="0 1.5707 1.5707" xyz="0 0 0"/>
      <geometry>
        <cylinder length="0.001" radius="0.0045000000000000005"/>
      </geometry>
    </collision>
    <inertial>
        <origin rpy="0 1.5707 1.5707" xyz="0 0 0"/>
        <mass value="0.001"/>
        <inertia ixx="5.145833333333334e-09" ixy="0" ixz="0" iyy="5.145833333333334e-09" iyz="0" izz="1.0125000000000003e-08"/>
    </inertial>
  </link>

  <joint name="back_roll_joint" type="continuous">
    <origin rpy="0 0 0" xyz="0 0 0" />
    <parent link="back_yaw_link" />
    <child link="back_roll_link" />
    <axis xyz="1 0 0" />
    <limit effort="1000.0" velocity="100.0" />
    <dynamics damping="0.0" friction="0.1"/>
  </joint>

  <link name="back_pitch_link">
    <visual>
      <origin rpy="0 1.5707 1.5707" xyz="0 0 0"/>
      <geometry>
        <sphere radius="0.010"/>
      </geometry>
    </visual>
    <collision>
      <origin rpy="0 1.5707 1.5707" xyz="0 0 0"/>
      <geometry>
        <sphere radius="0.010"/>
      </geometry>
    </collision>
    <inertial>
        <origin rpy="0 1.5707 1.5707" xyz="0 0 0"/>
        <mass value="0.001"/>
        <inertia ixx="4e-08" ixy="0" ixz="0" iyy="4e-08" iyz="0" izz="4e-08"/>
    </inertial>
  </link>

  <joint name="back_pitch_joint" type="continuous">
    <origin rpy="0 0 0" xyz="0 0 0" />
    <parent link="back_roll_link" />
    <child link="back_pitch_link" />
    <axis xyz="0 1 0" />
    <limit effort="1000.0" velocity="100.0" />
    <dynamics damping="0.0" friction="0.1"/>
  </joint>

   <!-- Standoff 1 -->
  <link name="standoff_1">
    <visual>
      <origin xyz="0 0 0.11"/>
      <geometry>
        <cylinder length="0.22" radius="0.01"/>
      </geometry>
    </visual>
    <collision>
      <origin xyz="0 0 0.11"/>
      <geometry>
        <cylinder length="0.22" radius="0.01"/>
      </geometry>
    </collision>
    <inertial>
      <mass value="0.05"/>
      <origin xyz="0 0 0.11" rpy="0 0 0"/>
      <inertia ixx="0.0002029" ixy="0.0" ixz="0.0" iyy="0.0002029" iyz="0.0" izz="0.0000025"/>
    </inertial>
  </link>

  <joint name="joint_standoff_1" type="fixed">
    <origin xyz="0.1 0.1 0.0775" />
    <parent link="base_link"/>
    <child link="standoff_1"/>
  </joint>

   <!-- Standoff 2 -->
  <link name="standoff_2">
    <visual>
      <origin xyz="0 0 0.11"/>
      <geometry>
        <cylinder length="0.22" radius="0.01"/>
      </geometry>
    </visual>
    <collision>
      <origin xyz="0 0 0.11"/>
      <geometry>
        <cylinder length="0.22" radius="0.01"/>
      </geometry>
    </collision>
    <inertial>
      <mass value="0.05"/>
      <origin xyz="0 0 0.11" rpy="0 0 0"/>
      <inertia ixx="0.0002029" ixy="0.0" ixz="0.0" iyy="0.0002029" iyz="0.0" izz="0.0000025"/>
    </inertial>
  </link>

  <joint name="joint_standoff_2" type="fixed">
    <origin xyz="0.1 -0.1 0.0775" />
    <parent link="base_link"/>
    <child link="standoff_2"/>
  </joint>

   <!-- Standoff 3 -->
  <link name="standoff_3">
    <visual>
      <origin xyz="0 0 0.11"/>
      <geometry>
        <cylinder length="0.22" radius="0.01"/>
      </geometry>
    </visual>
    <collision>
      <origin xyz="0 0 0.11"/>
      <geometry>
        <cylinder length="0.22" radius="0.01"/>
      </geometry>
    </collision>
    <inertial>
      <mass value="0.05"/>
      <origin xyz="0 0 0.11" rpy="0 0 0"/>
      <inertia ixx="0.0002029" ixy="0.0" ixz="0.0" iyy="0.0002029" iyz="0.0" izz="0.0000025"/>
    </inertial>
  </link>

  <joint name="joint_standoff_3" type="fixed">
    <origin xyz="-0.1 -0.1 0.0775" />
    <parent link="base_link"/>
    <child link="standoff_3"/>
  </joint>

   <!-- Standoff 4 -->
  <link name="standoff_4">
    <visual>
      <origin xyz="0 0 0.11"/>
      <geometry>
        <cylinder length="0.22" radius="0.01"/>
      </geometry>
    </visual>
    <collision>
      <origin xyz="0 0 0.11"/>
      <geometry>
        <cylinder length="0.22" radius="0.01"/>
      </geometry>
    </collision>
    <inertial>
      <mass value="0.05"/>
      <origin xyz="0 0 0.11" rpy="0 0 0"/>
      <inertia ixx="0.0002029" ixy="0.0" ixz="0.0" iyy="0.0002029" iyz="0.0" izz="0.0000025"/>
    </inertial>
  </link>

  <joint name="joint_standoff_4" type="fixed">
    <origin xyz="-0.1 0.1 0.0775" />
    <parent link="base_link"/>
    <child link="standoff_4"/>
  </joint>

  <!-- Tray -->
  <link name="tray">
    <visual>
      <origin xyz="0 0 0.045"/>
      <geometry>
        <cylinder length="0.09" radius="0.16"/>
      </geometry>
    </visual>
    <collision>
      <origin xyz="0 0 0.045"/>
      <geometry>
        <cylinder length="0.09" radius="0.16"/>
      </geometry>
    </collision>
    <inertial>
      <origin xyz="0 0 0.045"/>
      <mass value="0.3"/>
      <inertia ixx="0.0021225" ixy="0.0" ixz="0.0" iyy="0.0021225" iyz="0.0" izz="0.00384"/>
    </inertial>
  </link>
  
  <joint name="joint_tray" type="fixed">
    <origin xyz="0 0 0.2975"/>
    <parent link="base_link"/>
    <child link="tray"/>
  </joint>

</robot>